Workbook

Sheet Verifica red EN PULG 
B2: VERIFICADOR DE SISTEMAS ABIERTOS DE AGUA POTABLE
A5: 1.- | B5: NOMBRE DEL PROYECTO | E5: : | F5: AGUA POTABLE -CRUZ PATA
A6: 2.- | B6: NUMERO DEL EXPEDIENTE | E6: : | F6: 24980012
A7: 3.- | B7: OFICINA ZONAL | E7: : | F7: ABANCAY
A9: A.- | B9: POBLACION ACTUAL | I9: 240
A10: B.- | B10: TASA DE CRECIMIENTO (%) | I10: 2
A11: C.- | B11: PERIODO DE DISEÑO (AÑOS) | I11: 20
A12: D.- | B12: POBLACION FUTURA | F12: Pf = Po * ( 1+ r*t/100 ) | I12: =IF(OR(OR(I9=0,I10=0),I11=0),"",+I9*(1+(I10*I11/100))) -> 336
A14: E.- | B14: DOTACION (LT/HAB/DIA) | I14: 70
A16: F.- | B16: CONSUMO PROMEDIO ANUAL (LT/SEG) | F16: Q = Pob.* Dot./86,400 | I16: =IF(OR(I12=0,I12=0),"",+I12*I14/86400) -> 0.27222222
A18: G.- | B18: CONSUMO MAXIMO DIARIO (LT/SEG) | F18: Qmd = 1.30 * Q | I18: =IF(I12=0,"",1.3*I16) -> 0.35388889 | J18: =IF(I20<I18,"LA FUENTE NO ABASTECE","OK.") -> OK.
A20: H.- | B20: CAUDAL DE LA FUENTE (LT/SEG) | I20: 5
G21: Marcar con "1" lo correcto:
A22: I.- | B22: VOLUMEN DEL RESERVORIO (M3) | M22: =+IF(H24=1,"horas de bombeo = ","") | N22: 12
B23: V = 0.25 * Qmp *86400/1000 | F23: BOMBEO: | G23: NO | H23: 1 | N23: RESERVORIO PROPUESTO
B24: (sí es por Bombeo sera el 30 %) | G24: SI | I24: =IF(AND(H24=0,H23=0),"",IF(AND(H24=0,H23=1),0.25*I16*86.4,0.3*I16*86.4)) -> 5.88 | J24: =IF(H24=1,I18*24/N22,"") | N24: POR PROYECTISTA
L25: Si el reservorio es cilindrico, y: | M25: 2.6 | N25: 2.6
G26: A UTILIZAR : | I26: =+ROUNDUP(I24,0) -> 6 | J26: =IF(I26<I24,"EL VOLUMEN DEBE SER MAYOR","OK.") -> OK. | L26: Entonces: | M26: =+(I26/PI()/M25)^0.5 -> 0.8570655 | N26: 2.27
N27: Vpropuesto = | O27: =+PI()*N26*N25 -> 18.54168
A28: J.- | B28: CONSUMO MAXIMO HORARIO (LT/SEG) | F28: Qmh = 2 * Qmd = 2.60 Q | I28: =IF(I16=0,"",+I16*G29) -> 0.68055556
F29: k2= | G29: 2.5
B31: LINEA DE CONDUCCION
B32: Elemento | C32: Nivel Dinámico | D32: Longitud (Km) | E32: Caudal tramo | F32: Pendiente S | G32: Diámetro en " | H32: Diám. Comercial | I32: Velocidad Flujo | J32: Hf | K32: H. Piezométrica | L32: Presión
K33: =IF(C33=0,"",C33)
B34: Captación | C34: 2975.44 | E34: =IF(OR(OR($I$18=0,C34=0),D34=0),"",$I$18) | F34: =IF(OR(OR(C33=0,C34=0),D34=0),"",((C33-C34)/D34)) | G34: =IF(OR(E34=0,F34=0),"",(E34/(0.0597*(F34^0.54)))^(1/2.63)) | I34: =IF(OR(E34=0,H34=0),"",(E34/(3141.6*0.25*(H34*0.0254)^2))) | J34: =IF(OR(OR(E34=0,D34=0),H34=0),"",(1.72*10^6*D34*E34^1.85/140^1.85/H34^4.87)) | K34: =+C34 -> 2975.44 | L34: =IF(OR(C34=0,K34=0),"",+K34-C34) -> 0
B35: 1 | C35: 2900 | D35: 0.573 | E35: =+I18 -> 0.35388889 | F35: =IF(OR(OR(C34=0,C35=0),D35=0),"",((C34-C35)/D35)) -> 131.65794 | G35: =IF(OR(E35=0,F35=0),"",(E35/(0.0597*(F35^0.54)))^(1/2.63)) -> 0.72227714 | H35: 2 | I35: =IF(OR(E35=0,H35=0),"",(E35/(3141.6*0.25*(H35*0.0254)^2))) -> 0.17460176 | J35: =IF(OR(OR(E35=0,D35=0),H35=0),"",(1.72*10^6*D35*E35^1.85/140^1.85/H35^4.87)) -> 0.52812161 | K35: =IF(OR(C34=0,J35=0),"",C34-J35) -> 2974.9119 | L35: =IF(OR(C35=0,K35=0),"",+K35-C35) -> 74.911878
B36: 2 | C36: 2825 | D36: 0.193 | E36: =IF(OR(OR($I$18=0,C36=0),D36=0),"",$I$18) -> 0.35388889 | F36: =IF(OR(OR(C35=0,C36=0),D36=0),"",((C35-C36)/D36)) -> 388.60104 | G36: =IF(OR(E36=0,F36=0),"",(E36/(0.0597*(F36^0.54)))^(1/2.63)) -> 0.5783494 | H36: 2 | I36: =IF(OR(E36=0,H36=0),"",(E36/(3141.6*0.25*(H36*0.0254)^2))) -> 0.17460176 | J36: =IF(OR(OR(E36=0,D36=0),H36=0),"",(1.72*10^6*D36*E36^1.85/140^1.85/H36^4.87)) -> 0.17788389 | K36: =IF(OR(C35=0,J36=0),"",C35-J36) -> 2899.8221 | L36: =IF(OR(C36=0,K36=0),"",+K36-C36) -> 74.822116
B37: 3 | C37: 2750 | D37: 3.389 | E37: =IF(OR(OR($I$18=0,C37=0),D37=0),"",$I$18) -> 0.35388889 | F37: =IF(OR(OR(C36=0,C37=0),D37=0),"",((C36-C37)/D37)) -> 22.130422 | G37: =IF(OR(E37=0,F37=0),"",(E37/(0.0597*(F37^0.54)))^(1/2.63)) -> 1.0416407 | H37: 2.5 | I37: =IF(OR(E37=0,H37=0),"",(E37/(3141.6*0.25*(H37*0.0254)^2))) -> 0.11174512 | J37: =IF(OR(OR(E37=0,D37=0),H37=0),"",(1.72*10^6*D37*E37^1.85/140^1.85/H37^4.87)) -> 1.0536567 | K37: =IF(OR(C36=0,J37=0),"",C36-J37) -> 2823.9463 | L37: =IF(OR(C37=0,K37=0),"",+K37-C37) -> 73.946343
B38: 4 | C38: 2675 | D38: 1.671 | E38: =IF(OR(OR($I$18=0,C38=0),D38=0),"",$I$18) -> 0.35388889 | F38: =IF(OR(OR(C37=0,C38=0),D38=0),"",((C37-C38)/D38)) -> 44.883303 | G38: =IF(OR(E38=0,F38=0),"",(E38/(0.0597*(F38^0.54)))^(1/2.63)) -> 0.90087427 | H38: 2 | I38: =IF(OR(E38=0,H38=0),"",(E38/(3141.6*0.25*(H38*0.0254)^2))) -> 0.17460176 | J38: =IF(OR(OR(E38=0,D38=0),H38=0),"",(1.72*10^6*D38*E38^1.85/140^1.85/H38^4.87)) -> 1.5401243 | K38: =IF(OR(C37=0,J38=0),"",C37-J38) -> 2748.4599 | L38: =IF(OR(C38=0,K38=0),"",+K38-C38) -> 73.459876
B39: 5 | C39: 2600 | D39: 0.441 | E39: =IF(OR(OR($I$18=0,C39=0),D39=0),"",$I$18) -> 0.35388889 | F39: =IF(OR(OR(C38=0,C39=0),D39=0),"",((C38-C39)/D39)) -> 170.06803 | G39: =IF(OR(E39=0,F39=0),"",(E39/(0.0597*(F39^0.54)))^(1/2.63)) -> 0.68529402 | H39: 1.5 | I39: =IF(OR(E39=0,H39=0),"",(E39/(3141.6*0.25*(H39*0.0254)^2))) -> 0.31040312 | J39: =IF(OR(OR(E39=0,D39=0),H39=0),"",(1.72*10^6*D39*E39^1.85/140^1.85/H39^4.87)) -> 1.6499453 | K39: =IF(OR(C38=0,J39=0),"",C38-J39) -> 2673.3501 | L39: =IF(OR(C39=0,K39=0),"",+K39-C39) -> 73.350055
B40: 6 | C40: 2525 | D40: 0.168 | E40: =IF(OR(OR($I$18=0,C40=0),D40=0),"",$I$18) -> 0.35388889 | F40: =IF(OR(OR(C39=0,C40=0),D40=0),"",((C39-C40)/D40)) -> 446.42857 | G40: =IF(OR(E40=0,F40=0),"",(E40/(0.0597*(F40^0.54)))^(1/2.63)) -> 0.56210827 | H40: 1.5 | I40: =IF(OR(E40=0,H40=0),"",(E40/(3141.6*0.25*(H40*0.0254)^2))) -> 0.31040312 | J40: =IF(OR(OR(E40=0,D40=0),H40=0),"",(1.72*10^6*D40*E40^1.85/140^1.85/H40^4.87)) -> 0.6285506 | K40: =IF(OR(C39=0,J40=0),"",C39-J40) -> 2599.3714 | L40: =IF(OR(C40=0,K40=0),"",+K40-C40) -> 74.371449
B41: 7 | C41: 2450 | D41: 0.099 | E41: =IF(OR(OR($I$18=0,C41=0),D41=0),"",$I$18) -> 0.35388889 | F41: =IF(OR(OR(C40=0,C41=0),D41=0),"",((C40-C41)/D41)) -> 757.57576 | G41: =IF(OR(E41=0,F41=0),"",(E41/(0.0597*(F41^0.54)))^(1/2.63)) -> 0.50426933 | H41: 1.5 | I41: =IF(OR(E41=0,H41=0),"",(E41/(3141.6*0.25*(H41*0.0254)^2))) -> 0.31040312 | J41: =IF(OR(OR(E41=0,D41=0),H41=0),"",(1.72*10^6*D41*E41^1.85/140^1.85/H41^4.87)) -> 0.37039589 | K41: =IF(OR(C40=0,J41=0),"",C40-J41) -> 2524.6296 | L41: =IF(OR(C41=0,K41=0),"",+K41-C41) -> 74.629604
B42: 8 | C42: 2375 | D42: 0.13 | E42: =IF(OR(OR($I$18=0,C42=0),D42=0),"",$I$18) -> 0.35388889 | F42: =IF(OR(OR(C41=0,C42=0),D42=0),"",((C41-C42)/D42)) -> 576.92308 | G42: =IF(OR(E42=0,F42=0),"",(E42/(0.0597*(F42^0.54)))^(1/2.63)) -> 0.53327836 | H42: 1.5 | I42: =IF(OR(E42=0,H42=0),"",(E42/(3141.6*0.25*(H42*0.0254)^2))) -> 0.31040312 | J42: =IF(OR(OR(E42=0,D42=0),H42=0),"",(1.72*10^6*D42*E42^1.85/140^1.85/H42^4.87)) -> 0.48637844 | K42: =IF(OR(C41=0,J42=0),"",C41-J42) -> 2449.5136 | L42: =IF(OR(C42=0,K42=0),"",+K42-C42) -> 74.513622
B43: 9 | C43: 2300 | D43: 0.16 | E43: =IF(OR(OR($I$18=0,C43=0),D43=0),"",$I$18) -> 0.35388889 | F43: =IF(OR(OR(C42=0,C43=0),D43=0),"",((C42-C43)/D43)) -> 468.75 | G43: =IF(OR(E43=0,F43=0),"",(E43/(0.0597*(F43^0.54)))^(1/2.63)) -> 0.55650532 | H43: 1.5 | I43: =IF(OR(E43=0,H43=0),"",(E43/(3141.6*0.25*(H43*0.0254)^2))) -> 0.31040312 | J43: =IF(OR(OR(E43=0,D43=0),H43=0),"",(1.72*10^6*D43*E43^1.85/140^1.85/H43^4.87)) -> 0.59861962 | K43: =IF(OR(C42=0,J43=0),"",C42-J43) -> 2374.4014 | L43: =IF(OR(C43=0,K43=0),"",+K43-C43) -> 74.40138
B44: 10 | C44: 2225 | D44: 0.117 | E44: =IF(OR(OR($I$18=0,C44=0),D44=0),"",$I$18) -> 0.35388889 | F44: =IF(OR(OR(C43=0,C44=0),D44=0),"",((C43-C44)/D44)) -> 641.02564 | G44: =IF(OR(E44=0,F44=0),"",(E44/(0.0597*(F44^0.54)))^(1/2.63)) -> 0.52186586 | H44: 1.5 | I44: =IF(OR(E44=0,H44=0),"",(E44/(3141.6*0.25*(H44*0.0254)^2))) -> 0.31040312 | J44: =IF(OR(OR(E44=0,D44=0),H44=0),"",(1.72*10^6*D44*E44^1.85/140^1.85/H44^4.87)) -> 0.4377406 | K44: =IF(OR(C43=0,J44=0),"",C43-J44) -> 2299.5623 | L44: =IF(OR(C44=0,K44=0),"",+K44-C44) -> 74.562259
B45: 11 | C45: 2154 | D45: 0.222 | E45: =IF(OR(OR($I$18=0,C45=0),D45=0),"",$I$18) -> 0.35388889 | F45: =IF(OR(OR(C44=0,C45=0),D45=0),"",((C44-C45)/D45)) -> 319.81982 | G45: =IF(OR(E45=0,F45=0),"",(E45/(0.0597*(F45^0.54)))^(1/2.63)) -> 0.60194989 | H45: 1.5 | I45: =IF(OR(E45=0,H45=0),"",(E45/(3141.6*0.25*(H45*0.0254)^2))) -> 0.31040312 | J45: =IF(OR(OR(E45=0,D45=0),H45=0),"",(1.72*10^6*D45*E45^1.85/140^1.85/H45^4.87)) -> 0.83058472 | K45: =IF(OR(C43=0,J45=0),"",C43-J45) -> 2299.1694 | L45: =IF(OR(C45=0,K45=0),"",+K45-C45) -> 145.16942
B46: RESERVORIO | C46: 2149.08 | D46: 0.043 | E46: =IF(OR(OR($I$18=0,C46=0),D46=0),"",$I$18) -> 0.35388889 | F46: =IF(OR(OR(C45=0,C46=0),D46=0),"",((C45-C46)/D46)) -> 114.4186 | G46: =IF(OR(E46=0,F46=0),"",(E46/(0.0597*(F46^0.54)))^(1/2.63)) -> 0.74339289 | H46: 1.5 | I46: =IF(OR(E46=0,H46=0),"",(E46/(3141.6*0.25*(H46*0.0254)^2))) -> 0.31040312 | J46: =IF(OR(OR(E46=0,D46=0),H46=0),"",(1.72*10^6*D46*E46^1.85/140^1.85/H46^4.87)) -> 0.16087902 | K46: =IF(OR(C44=0,J46=0),"",C44-J46) -> 2224.8391 | L46: =IF(OR(C46=0,K46=0),"",+K46-C46) -> 75.759121
D47: 7.205
B49: NOTA: LA CLASE DE TUBERÍA A UTILIZAR PARA LA LINEA DE CONDUCCION SERÁ CL-10
B51: RED DE DISTRIBUCION | O51: N`
...

Sheet EJEMPLO 01 EN MM
E3: Poblaciones con crecimiento Horizontal a travez de una via principal o un rio
P4: Pf= | Q4: 731
P5: Qp= | Q5: 0.85 | T5: =+T4/H13 -> 0
P6: Qmd= | Q6: =0.85*1.3 -> 1.105 | R6: K1=1.3
P7: Qmh= | Q7: =+Q5*2 -> 1.7 | R7: k2=2
E8: qu: | F8: Caudal Unitario | H8: qu= | I8: =+Q7/Q4 -> 0.0023255814 | K8: Lts/Hab/Dia | N8: ^ | P8: Dens. Pobl= | Q8: 5
F10: Caudal x Tramo | G10: Diseño | H10: Long de tramo | K10: Diametro | L10: Velocidad | O10: C(PVC) | P10: 150
P11: Piezometrica | T11: 61.037
A12: TRAMO | C12: Cota inicio | D12: Cota fin | E12: N° viviendas | F12: Qu (por tramo) | G12: Q(Diseño) | H12: Longitud (m) | I12: S (teorico) | J12: D(real) pulg | K12: Dcomercial (pulg) | L12: (mm) | M12: Vel (m/seg) | N12: Sr= | O12: Hf | P12: Cpi | Q12: CPf | R12: Pi | S12: Pf
A13: RES | B13: A | C13: 2550 | D13: 2527 | E13: 0 | F13: =ROUND(E13*$Q$8*$I$8,3) -> 0 | G13: =+G14+G19 -> 1.711 | H13: 140 | I13: =((C13-D13)/H13)*1000 -> 164.28571 | J13: =(G13/(0.0004264*$P$10*(I13^0.54)))^(1/2.63) -> 1.2240563 | K13: 1.5 | L13: =IF(K13=1,29.4,IF(K13=1.5,43.4,IF(K13=0.75,22.9,IF(K13=0.5,17.4)))) -> 43.4 | M13: =ROUND((4*G13/1000)/(((L13/1000)^2)*3.1416),2) -> 1.16 | N13: =ROUND(((G13/(0.0004264*$P$10*((L13/25.4)^2.63)))^1.852),2) -> 32.38 | O13: =ROUND(+H13*N13/1000,2) -> 4.53 | P13: =+C13 -> 2550 | Q13: =+P13-O13 -> 2545.47 | R13: =P13-C13 -> 0 | S13: =Q13-D13 -> 18.47
A14: A | B14: B | C14: =+D13 -> 2527 | D14: 2512 | E14: 10 | F14: =ROUND(E14*$Q$8*$I$8,3) -> 0.116 | G14: =+G17+G15+F14 -> 0.222 | H14: 75 | I14: =+(C14-D14+S13)*1000/H14 -> 446.26667 | J14: =(G14/(0.0004264*$P$10*(I14^0.54)))^(1/2.63) -> 0.45863693 | K14: 0.75 | L14: =IF(K14=1,29.4,IF(K14=1.5,43.4,IF(K14=0.75,22.9,IF(K14=0.5,17.4)))) -> 22.9 | M14: =ROUND((4*G14/1000)/(((L14/1000)^2)*3.1416),2) -> 0.54 | N14: =ROUND(((G14/(0.0004264*$P$10*((L14/25.4)^2.63)))^1.852),2) -> 16.6 | O14: =ROUND(+H14*N14/1000,2) -> 1.25 | P14: =+Q13 -> 2545.47 | Q14: =+P14-O14 -> 2544.22 | R14: =+S13 -> 18.47 | S14: =+Q14-D14 -> 32.22 | T14: 446.26667
A15: B | B15: CRP 02 | C15: =+D14 -> 2512 | D15: 2500 | E15: 4 | F15: =ROUND(E15*$Q$8*$I$8,3) -> 0.047 | G15: =+F16+F15 -> 0.082 | H15: 50 | I15: =+(C15-D15+S14)*1000/H15 -> 884.4 | J15: =(G15/(0.0004264*$P$10*(I15^0.54)))^(1/2.63) -> 0.27290616 | K15: 0.75 | L15: =IF(K15=1,29.4,IF(K15=1.5,43.4,IF(K15=0.75,22.9,IF(K15=0.5,17.4)))) -> 22.9 | M15: =ROUND((4*G15/1000)/(((L15/1000)^2)*3.1416),2) -> 0.2 | N15: =ROUND(((G15/(0.0004264*$P$10*((L15/25.4)^2.63)))^1.852),2) -> 2.62 | O15: =ROUND(+H15*N15/1000,2) -> 0.13 | P15: =+Q14 -> 2544.22 | Q15: =+P15-O15 -> 2544.09 | R15: =+S14 -> 32.22 | S15: =+Q15-D15 -> 44.09 | T15: 884.4
A16: CRP 02 | B16: C | C16: 2500 | D16: 2487 | E16: 3 | F16: =ROUND(E16*$Q$8*$I$8,3) -> 0.035 | G16: =+F16 -> 0.035 | H16: 50 | I16: =+(C16-D16)*1000/H16 -> 260 | J16: =(G16/(0.0004264*$P$10*(I16^0.54)))^(1/2.63) -> 0.25385801 | K16: 0.75 | L16: =IF(K16=1,29.4,IF(K16=1.5,43.4,IF(K16=0.75,22.9,IF(K16=0.5,17.4)))) -> 22.9 | M16: =ROUND((4*G16/1000)/(((L16/1000)^2)*3.1416),2) -> 0.08 | N16: =ROUND(((G16/(0.0004264*$P$10*((L16/25.4)^2.63)))^1.852),2) -> 0.54 | O16: =ROUND(+H16*N16/1000,2) -> 0.03 | P16: =+C16 -> 2500 | Q16: =+P16-O16 -> 2499.97 | R16: 0 | S16: =+Q16-D16 -> 12.97 | T16: 1141.8
A17: B | B17: CRP 03 | C17: 2512 | D17: 2500 | E17: 1 | F17: =ROUND(E17*$Q$8*$I$8,3) -> 0.012 | G17: =+F18+F17 -> 0.024 | H17: 50 | I17: =+(C17-D17+S14)*1000/H17 -> 884.4 | J17: =(G17/(0.0004264*$P$10*(I17^0.54)))^(1/2.63) -> 0.17104982 | K17: 0.75 | L17: =IF(K17=1,29.4,IF(K17=1.5,43.4,IF(K17=0.75,22.9,IF(K17=0.5,17.4)))) -> 22.9 | M17: =ROUND((4*G17/1000)/(((L17/1000)^2)*3.1416),2) -> 0.06 | N17: =ROUND(((G17/(0.0004264*$P$10*((L17/25.4)^2.63)))^1.852),2) -> 0.27 | O17: =ROUND(+H17*N17/1000,2) -> 0.01 | P17: =+Q14 -> 2544.22 | Q17: =+P17-O17 -> 2544.21 | R17: =+S14 -> 32.22 | S17: =+Q17-D17 -> 44.21 | T17: 884.4
A18: CRP 03 | B18: D | C18: 2500 | D18: 2492 | E18: 1 | F18: =ROUND(E18*$Q$8*$I$8,3) -> 0.012 | G18: =+F18 -> 0.012 | H18: 30 | I18: =+(C18-D18+0)*1000/H18 -> 266.66667 | J18: =(G18/(0.0004264*$P$10*(I18^0.54)))^(1/2.63) -> 0.16810097 | K18: 0.75 | L18: =IF(K18=1,29.4,IF(K18=1.5,43.4,IF(K18=0.75,22.9,IF(K18=0.5,17.4)))) -> 22.9 | M18: =ROUND((4*G18/1000)/(((L18/1000)^2)*3.1416),2) -> 0.03 | N18: =ROUND(((G18/(0.0004264*$P$10*((L18/25.4)^2.63)))^1.852),2) -> 0.07 | O18: =ROUND(+H18*N18/1000,2) -> 0 | P18: =+C18 -> 2500 | Q18: =+P18-O18 -> 2500 | R18: =+P18-C18 -> 0 | S18: =+Q18-D18 -> 8 | T18: 1740.3333
A19: A | B19: E | C19: =+C14 -> 2527 | D19: 2500 | E19: =35+10 -> 45 | F19: =ROUND(E19*$Q$8*$I$8,3) -> 0.523 | G19: =+G20+G21+F19 -> 1.489 | H19: 220 | I19: =+(C19-D19+S13)*1000/H19 -> 206.68182 | J19: =(G19/(0.0004264*$P$10*(I19^0.54)))^(1/2.63) -> 1.107596 | K19: 1.5 | L19: =IF(K19=1,29.4,IF(K19=1.5,43.4,IF(K19=0.75,22.9,IF(K19=0.5,17.4)))) -> 43.4 | M19: =ROUND((4*G19/1000)/(((L19/1000)^2)*3.1416),2) -> 1.01 | N19: =ROUND(((G19/(0.0004264*$P$10*((L19/25.4)^2.63)))^1.852),2) -> 25.03 | O19: =ROUND(+H19*N19/1000,2) -> 5.51 | P19: =+Q13 -> 2545.47 | Q19: =+P19-O19 -> 2539.96 | R19: =+S13 -> 18.47 | S19: =+Q19-D19 -> 39.96 | T19: 206.68182
A20: E | B20: F | C20: =+D19 -> 2500 | D20: 2497 | E20: 16 | F20: =ROUND(E20*$Q$8*$I$8,3) -> 0.186 | G20: =+F20 -> 0.186 | H20: 130 | I20: =+(C20-D20+S19)*1000/H20 -> 330.46154 | J20: =(G20/(0.0004264*$P$10*(I20^0.54)))^(1/2.63) -> 0.45608051 | K20: 0.75 | L20: =IF(K20=1,29.4,IF(K20=1.5,43.4,IF(K20=0.75,22.9,IF(K20=0.5,17.4)))) -> 22.9 | M20: =ROUND((4*G20/1000)/(((L20/1000)^2)*3.1416),2) -> 0.45 | N20: =ROUND(((G20/(0.0004264*$P$10*((L20/25.4)^2.63)))^1.852),2) -> 11.96 | O20: =ROUND(+H20*N20/1000,2) -> 1.55 | P20: =+Q19 -> 2539.96 | Q20: =+P20-O20 -> 2538.41 | R20: =+S19 -> 39.96 | S20: =+Q20-D20 -> 41.41 | T20: 330.46154
A21: E | B21: CRP 01 | C21: =+C20 -> 2500 | D21: 2500 | E21: 0 | F21: =ROUND(E21*$Q$8*$I$8,3) -> 0 | G21: =+G22+F21 -> 0.78 | H21: 1 | I21: =+(C21-D21+S19)*1000/H21 -> 39960 | J21: =(G21/(0.0004264*$P$10*(I21^0.54)))^(1/2.63) -> 0.29388546 | K21: 1 | L21: =IF(K21=1,29.4,IF(K21=1.5,43.4,IF(K21=0.75,22.9,IF(K21=0.5,17.4)))) -> 29.4 | M21: =ROUND((4*G21/1000)/(((L21/1000)^2)*3.1416),2) -> 1.15 | N21: =ROUND(((G21/(0.0004264*$P$10*((L21/25.4)^2.63)))^1.852),2) -> 50.38 | O21: =ROUND(+H21*N21/1000,2) -> 0.05 | P21: =+P20 -> 2539.96 | Q21: =+P21-O21 -> 2539.91 | R21: =+R20 -> 39.96 | S21: =+Q21-D21 -> 39.91 | T21: 41960
A22: CRP 01 | B22: G | C22: =+D21 -> 2500 | D22: 2480 | E22: =20+10 -> 30 | F22: =ROUND(E22*$Q$8*$I$8,3) -> 0.349 | G22: =+F24+F23+F22 -> 0.78 | H22: 90 | I22: =+(C22-D22+0)*1000/H22 -> 222.22222 | J22: =(G22/(0.0004264*$P$10*(I22^0.54)))^(1/2.63) -> 0.85339213 | K22: 1 | L22: =IF(K22=1,29.4,IF(K22=1.5,43.4,IF(K22=0.75,22.9,IF(K22=0.5,17.4)))) -> 29.4 | M22: =ROUND((4*G22/1000)/(((L22/1000)^2)*3.1416),2) -> 1.15 | N22: =ROUND(((G22/(0.0004264*$P$10*((L22/25.4)^2.63)))^1.852),2) -> 50.38 | O22: =ROUND(+H22*N22/1000,2) -> 4.53 | P22: =+C22 -> 2500 | Q22: =+P22-O22 -> 2495.47 | R22: =+P22-C22 -> 0 | S22: =+Q22-D22 -> 15.47 | T22: 665.66667
A23: G | B23: H | C23: =+D22 -> 2480 | D23: 2463 | E23: =10+2 -> 12 | F23: =ROUND(E23*$Q$8*$I$8,3) -> 0.14 | G23: =+F23 -> 0.14 | H23: 40 | I23: =+(C23-D23+S22)*1000/H23 -> 811.75 | J23: =(G23/(0.0004264*$P$10*(I23^0.54)))^(1/2.63) -> 0.34039971 | K23: 0.75 | L23: =IF(K23=1,29.4,IF(K23=1.5,43.4,IF(K23=0.75,22.9,IF(K23=0.5,17.4)))) -> 22.9 | M23: =ROUND((4*G23/1000)/(((L23/1000)^2)*3.1416),2) -> 0.34 | N23: =ROUND(((G23/(0.0004264*$P$10*((L23/25.4)^2.63)))^1.852),2) -> 7.07 | O23: =ROUND(+H23*N23/1000,2) -> 0.28 | P23: =+Q22 -> 2495.47 | Q23: =+P23-O23 -> 2495.19 | R23: =+S22 -> 15.47 | S23: =+Q23-D23 -> 32.19 | T23: 761.75
A24: G | B24: I | C24: =+C23 -> 2480 | D24: 2467 | E24: =15+10 -> 25 | F24: =ROUND(E24*$Q$8*$I$8,3) -> 0.291 | G24: =+F24 -> 0.291 | H24: 115 | I24: =+(C24-D24+S22)*1000/H24 -> 247.56522 | J24: =(G24/(0.0004264*$P$10*(I24^0.54)))^(1/2.63) -> 0.57372561 | K24: 0.75 | L24: =IF(K24=1,29.4,IF(K24=1.5,43.4,IF(K24=0.75,22.9,IF(K24=0.5,17.4)))) -> 22.9 | M24: =ROUND((4*G24/1000)/(((L24/1000)^2)*3.1416),2) -> 0.71 | N24: =ROUND(((G24/(0.0004264*$P$10*((L24/25.4)^2.63)))^1.852),2) -> 27.4 | O24: =ROUND(+H24*N24/1000,2) -> 3.15 | P24: =+P23 -> 2495.47 | Q24: =+P24-O24 -> 2492.32 | R24: =+R23 -> 15.47 | S24: =+Q24-D24 -> 25.32 | T24: 227.73913
E25: =SUM(E13:E24) -> 147
AC37: =IF(K37=1,H37,0) -> 0 | AD37: =IF(K37=1.5,H37,0) -> 0 | AE37: =IF(K37=0.75,H37,0) -> 0 | AF37: =IF(K37=0.5,H37,0) -> 0
AC38: =IF(K38=1,H38,0) -> 0 | AD38: =IF(K38=1.5,H38,0) -> 0 | AE38: =IF(K38=0.75,H38,0) -> 0 | AF38: =IF(K38=0.5,H38,0) -> 0
AC39: =IF(K39=1,H39,0) -> 0 | AD39: =IF(K39=1.5,H39,0) -> 0 | AE39: =IF(K39=0.75,H39,0) -> 0 | AF39: =IF(K39=0.5,H39,0) -> 0
AC40: =IF(K40=1,H40,0) -> 0 | AD40: =IF(K40=1.5,H40,0) -> 0 | AE40: =IF(K40=0.75,H40,0) -> 0 | AF40: =IF(K40=0.5,H40,0) -> 0
AC41: =IF(K41=1,H41,0) -> 0 | AD41: =IF(K41=1.5,H41,0) -> 0 | AE41: =IF(K41=0.75,H41,0) -> 0 | AF41: =IF(K41=0.5,H41,0) -> 0
AC42: =IF(K42=1,H42,0) -> 0 | AD42: =IF(K42=1.5,H42,0) -> 0 | AE42: =IF(K42=0.75,H42,0) -> 0 | AF42: =IF(K42=0.5,H42,0) -> 0
AC43: =IF(K43=1,H43,0) -> 0 | AD43: =IF(K43=1.5,H43,0) -> 0 | AE43: =IF(K43=0.75,H43,0) -> 0 | AF43: =IF(K43=0.5,H43,0) -> 0
AC44: =IF(K44=1,H44,0) -> 0 | AD44: =IF(K44=1.5,H44,0) -> 0 | AE44: =IF(K44=0.75,H44,0) -> 0 | AF44: =IF(K44=0.5,H44,0) -> 0
AC45: =IF(K45=1,H45,0) -> 0 | AD45: =IF(K45=1.5,H45,0) -> 0 | AE45: =IF(K45=0.75,H45,0) -> 0 | AF45: =IF(K45=0.5,H45,0) -> 0
AC46: =IF(K46=1,H46,0) -> 0 | AD46: =IF(K46=1.5,H46,0) -> 0 | AE46: =IF(K46=0.75,H46,0) -> 0 | AF46: =IF(K46=0.5,H46,0) -> 0
AC47: =IF(K47=1,H47,0) -> 0 | AD47: =IF(K47=1.5,H47,0) -> 0 | AE47: =IF(K47=0.75,H47,0) -> 0 | AF47: =IF(K47=0.5,H47,0) -> 0
AC48: =IF(K48=1,H48,0) -> 0 | AD48: =IF(K48=1.5,H48,0) -> 0 | AE48: =IF(K48=0.75,H48,0) -> 0 | AF48: =IF(K48=0.5,H48,0) -> 0
AC49: =IF(K49=1,H49,0) -> 0 | AD49: =IF(K49=1.5,H49,0) -> 0 | AE49: =IF(K49=0.75,H49,0) -> 0 | AF49: =IF(K49=0.5,H49,0) -> 0
X51: =SUM(AC13:AC49) -> 0 | Y51: =SUM(AD13:AD49) -> 0 | Z51: =SUM(AE13:AE49) -> 0 | AA51: =SUM(AF13:AF49) -> 0
X52: =X51/5.03 -> 0 | Y52: =Y51/5.03 -> 0 | Z52: =Z51/5.03 -> 0 | AA52: =AA51/5.03 -> 0

Sheet EJEMPLO 01 desarrol
E3: Poblaciones con crecimiento Horizontal a travez de una via principal o un rio
P4: Pf= | Q4: 731
P5: Qp= | Q5: 0.85 | T5: =+T4/H13 -> 0
P6: Qmd= | Q6: =0.85*1.3 -> 1.105 | R6: K1=1.3
P7: Qmh= | Q7: =+Q5*2 -> 1.7 | R7: k2=2
E8: qu: | F8: Caudal Unitario | H8: qu= | I8: =+Q7/Q4 -> 0.0023255814 | K8: Lts/Hab/Dia | N8: ^ | P8: Dens. Pobl= | Q8: 5
F10: Caudal x Tramo | G10: Diseño | H10: Long de tramo | K10: Diametro | L10: Velocidad | O10: C(PVC) | P10: 150 | R10: =+Q4/Q8 -> 146.2
P11: Piezometrica
A12: TRAMO | C12: Cota inicio | D12: Cota fin | E12: N° viviendas | F12: Qu (por tramo) | G12: Q(Diseño) | H12: Longitud (m) | I12: S (real) | J12: D(real) pulg | K12: Dcomercial (pulg) | L12: (mm) | M12: Vel (m/seg) | N12: S(diseño-comercial) | O12: Hf | P12: Cpi | Q12: CPf | R12: Pi | S12: Pf
A13: RES | B13: A | C13: 2550 | D13: 2527 | E13: 0 | F13: =ROUND(E13*$Q$8*$I$8,3) -> 0 | G13: =+F13+G14+G19 -> 1.711 | H13: 140 | I13: =((C13-D13)/H13)*1000 -> 164.28571 | J13: =(G13/(0.0004264*$P$10*(I13^0.54)))^(1/2.63) -> 1.2240563 | K13: 1.5 | L13: 43.4 | M13: =ROUND((4*G13/1000)/(((L13/1000)^2)*3.1416),2) -> 1.16 | N13: =ROUND(((G13/(0.0004264*$P$10*((L13/25.4)^2.63)))^1.852),2) -> 32.38 | O13: =ROUND(+H13*N13/1000,2) -> 4.53 | P13: =+C13 -> 2550 | Q13: =+P13-O13 -> 2545.47 | R13: =P13-C13 -> 0 | S13: =Q13-D13 -> 18.47
A14: A | B14: B | C14: =+D13 -> 2527 | D14: 2512 | E14: 10 | F14: =ROUND(E14*$Q$8*$I$8,3) -> 0.116 | G14: =+F14+G17+G15 -> 0.222 | H14: 75 | I14: =+(C14-D14+S13)*1000/H14 -> 446.26667 | J14: =(G14/(0.0004264*$P$10*(I14^0.54)))^(1/2.63) -> 0.45863693 | K14: 0.75 | L14: 22.9 | M14: =ROUND((4*G14/1000)/(((L14/1000)^2)*3.1416),2) -> 0.54 | N14: =ROUND(((G14/(0.0004264*$P$10*((L14/25.4)^2.63)))^1.852),2) -> 16.6 | O14: =H14*N14/1000 -> 1.245
A15: B | B15: CRP-2 | C15: =+D14 -> 2512 | D15: 2500 | E15: 4 | F15: =ROUND(E15*$Q$8*$I$8,3) -> 0.047 | G15: =+F15+G16 -> 0.082 | H15: 50 | I15: =+(C15-D15+S14)*1000/H15 -> 240 | J15: =(G15/(0.0004264*$P$10*(I15^0.54)))^(1/2.63) -> 0.35671066 | K15: 0.75
A16: CRP-2 | B16: C | C16: 2500 | D16: 2487 | E16: 3 | F16: =ROUND(E16*$Q$8*$I$8,3) -> 0.035 | G16: =+F16 -> 0.035 | H16: 50 | I16: =+(C16-D16)*1000/H16 -> 260 | J16: =(G16/(0.0004264*$P$10*(I16^0.54)))^(1/2.63) -> 0.25385801 | K16: 0.75
A17: B | B17: CRP-3 | C17: 2512 | D17: 2500 | E17: 1 | F17: =ROUND(E17*$Q$8*$I$8,3) -> 0.012 | G17: =+F17+G18 -> 0.024 | H17: 50 | I17: =+(C17-D17+S14)*1000/H17 -> 240 | J17: =(G17/(0.0004264*$P$10*(I17^0.54)))^(1/2.63) -> 0.2235761 | K17: 0.75
A18: CRP-3 | B18: D | C18: 2500 | D18: 2492 | E18: 1 | F18: =ROUND(E18*$Q$8*$I$8,3) -> 0.012 | G18: =+F18 -> 0.012 | H18: 30 | I18: =+(C18-D18+0)*1000/H18 -> 266.66667 | J18: =(G18/(0.0004264*$P$10*(I18^0.54)))^(1/2.63) -> 0.16810097 | K18: 0.75
A19: A | B19: E | C19: =+C14 -> 2527 | D19: 2500 | E19: =35+10 -> 45 | F19: =ROUND(E19*$Q$8*$I$8,3) -> 0.523 | G19: =+F19+G20+G21 -> 1.489 | H19: 220 | I19: =+(C19-D19+S13)*1000/H19 -> 206.68182 | J19: =(G19/(0.0004264*$P$10*(I19^0.54)))^(1/2.63) -> 1.107596 | K19: 1.5
A20: E | B20: F | C20: =+D19 -> 2500 | D20: 2497 | E20: 16 | F20: =ROUND(E20*$Q$8*$I$8,3) -> 0.186 | G20: =+F20 -> 0.186 | H20: 130 | I20: =+(C20-D20+S19)*1000/H20 -> 23.076923 | J20: =(G20/(0.0004264*$P$10*(I20^0.54)))^(1/2.63) -> 0.78774096 | K20: 0.75
A21: E | B21: CRP-1 | C21: =+C20 -> 2500 | D21: 2500 | E21: 0 | F21: =ROUND(E21*$Q$8*$I$8,3) -> 0 | G21: =+F21+G22 -> 0.78 | H21: 1 | I21: =+(C21-D21+S19)*1000/H21 -> 0 | J21: =(G21/(0.0004264*$P$10*(I21^0.54)))^(1/2.63) -> #DIV/0! | K21: 1
A22: CRP-1 | B22: G | C22: =+D21 -> 2500 | D22: 2480 | E22: =20+10 -> 30 | F22: =ROUND(E22*$Q$8*$I$8,3) -> 0.349 | G22: =+F22+G23+G24 -> 0.78 | H22: 90 | I22: =+(C22-D22+0)*1000/H22 -> 222.22222 | J22: =(G22/(0.0004264*$P$10*(I22^0.54)))^(1/2.63) -> 0.85339213 | K22: 1
A23: G | B23: H | C23: =+D22 -> 2480 | D23: 2463 | E23: =10+2 -> 12 | F23: =ROUND(E23*$Q$8*$I$8,3) -> 0.14 | G23: =+F23 -> 0.14 | H23: 40 | I23: =+(C23-D23+S22)*1000/H23 -> 425 | J23: =(G23/(0.0004264*$P$10*(I23^0.54)))^(1/2.63) -> 0.3887692 | K23: 0.75
A24: G | B24: I | C24: =+C23 -> 2480 | D24: 2467 | E24: =15+10 -> 25 | F24: =ROUND(E24*$Q$8*$I$8,3) -> 0.291 | G24: =+F24 -> 0.291 | H24: 115 | I24: =+(C24-D24+S22)*1000/H24 -> 113.04348 | J24: =(G24/(0.0004264*$P$10*(I24^0.54)))^(1/2.63) -> 0.67391529 | K24: 0.75
AC37: =IF(K37=1,H37,0) -> 0 | AD37: =IF(K37=1.5,H37,0) -> 0 | AE37: =IF(K37=0.75,H37,0) -> 0 | AF37: =IF(K37=0.5,H37,0) -> 0
AC38: =IF(K38=1,H38,0) -> 0 | AD38: =IF(K38=1.5,H38,0) -> 0 | AE38: =IF(K38=0.75,H38,0) -> 0 | AF38: =IF(K38=0.5,H38,0) -> 0
AC39: =IF(K39=1,H39,0) -> 0 | AD39: =IF(K39=1.5,H39,0) -> 0 | AE39: =IF(K39=0.75,H39,0) -> 0 | AF39: =IF(K39=0.5,H39,0) -> 0
AC40: =IF(K40=1,H40,0) -> 0 | AD40: =IF(K40=1.5,H40,0) -> 0 | AE40: =IF(K40=0.75,H40,0) -> 0 | AF40: =IF(K40=0.5,H40,0) -> 0
AC41: =IF(K41=1,H41,0) -> 0 | AD41: =IF(K41=1.5,H41,0) -> 0 | AE41: =IF(K41=0.75,H41,0) -> 0 | AF41: =IF(K41=0.5,H41,0) -> 0
AC42: =IF(K42=1,H42,0) -> 0 | AD42: =IF(K42=1.5,H42,0) -> 0 | AE42: =IF(K42=0.75,H42,0) -> 0 | AF42: =IF(K42=0.5,H42,0) -> 0
AC43: =IF(K43=1,H43,0) -> 0 | AD43: =IF(K43=1.5,H43,0) -> 0 | AE43: =IF(K43=0.75,H43,0) -> 0 | AF43: =IF(K43=0.5,H43,0) -> 0
AC44: =IF(K44=1,H44,0) -> 0 | AD44: =IF(K44=1.5,H44,0) -> 0 | AE44: =IF(K44=0.75,H44,0) -> 0 | AF44: =IF(K44=0.5,H44,0) -> 0
AC45: =IF(K45=1,H45,0) -> 0 | AD45: =IF(K45=1.5,H45,0) -> 0 | AE45: =IF(K45=0.75,H45,0) -> 0 | AF45: =IF(K45=0.5,H45,0) -> 0
AC46: =IF(K46=1,H46,0) -> 0 | AD46: =IF(K46=1.5,H46,0) -> 0 | AE46: =IF(K46=0.75,H46,0) -> 0 | AF46: =IF(K46=0.5,H46,0) -> 0
AC47: =IF(K47=1,H47,0) -> 0 | AD47: =IF(K47=1.5,H47,0) -> 0 | AE47: =IF(K47=0.75,H47,0) -> 0 | AF47: =IF(K47=0.5,H47,0) -> 0
AC48: =IF(K48=1,H48,0) -> 0 | AD48: =IF(K48=1.5,H48,0) -> 0 | AE48: =IF(K48=0.75,H48,0) -> 0 | AF48: =IF(K48=0.5,H48,0) -> 0
AC49: =IF(K49=1,H49,0) -> 0 | AD49: =IF(K49=1.5,H49,0) -> 0 | AE49: =IF(K49=0.75,H49,0) -> 0 | AF49: =IF(K49=0.5,H49,0) -> 0
X51: =SUM(AC13:AC49) -> 0 | Y51: =SUM(AD13:AD49) -> 0 | Z51: =SUM(AE13:AE49) -> 0 | AA51: =SUM(AF13:AF49) -> 0
X52: =X51/5.03 -> 0 | Y52: =Y51/5.03 -> 0 | Z52: =Z51/5.03 -> 0 | AA52: =AA51/5.03 -> 0
